Workbook

Sheet Inputs
A1: VYNDI 36-Month Fund & Materials Projection
A2: Editable planning workbook · approved-plan baseline · ₹ lakh unless stated
A4: Approved plan input | B4: Value | D4: Model | E4: Mix | F4: ASP ₹L | G4: Launch month
A5: Horizon start | B5: 46266 | D5: Longitude | E5: 0.2 | F5: 1.25 | G5: 14
A6: Commercial launch month | B6: 14 | D6: Latitude | E6: 0.6 | F6: 2.25 | G6: 14
A7: Altitude launch month | B7: 16 | D7: Altitude | E7: 0.2 | F7: 3.5 | G7: 16
A8: Demand multiplier | B8: 1 | D8: Total | E8: =SUM(E5:E7)
A9: Material buffer | B9: 0.15
A10: Cash collection assumption | B10: 0.8
A11: Opening cash (₹L) | B11: 1
A12: Cash floor (₹L) | B12: 15
A14: Gate | B14: Month | C14: Core ₹L | D14: Optional? | E14: Purpose
A15: T1 | B15: 1 | C15: 15 | D15: No | E15: Foundation
A16: T2 | B16: 3 | C16: 35 | D16: No | E16: Engineering
A17: T3 | B17: 6 | C17: 35 | D17: No | E17: Validation
A18: STBY | B18: 9 | C18: 25 | D18: Yes | E18: Contingent cash-gap cover
A19: T4 | B19: 10 | C19: 50 | D19: No | E19: Tooling / pilot
A20: T5 | B20: 14 | C20: 65 | D20: No | E20: Launch working capital
A21: Core total | C21: =SUM(C15:C17,C19:C20)
A24: Material / component | B24: Unit | C24: Per Longitude | D24: Per Latitude | E24: Per Altitude | F24: Unit cost ₹ | G24: Basis
A25: Aluminium/OEM frameset | B25: set | C25: 1 | D25: 0 | E25: 0 | F25: 45000 | G25: Planning assumption
A26: T700 prepreg | B26: kg | C26: 0 | D26: 3.2 | E26: 2.5 | F26: 3500 | G26: Editable; release against approved ply book
A27: T800 prepreg | B27: kg | C27: 0 | D27: 1.3 | E27: 2.2 | F27: 6500 | G27: Editable; release against approved ply book
A28: Resin & bonding system | B28: kg | C28: 0 | D28: 0.8 | E28: 0.9 | F28: 1800 | G28: Editable manufacturing assumption
A29: Paint & clear coat | B29: L | C29: 0.35 | D29: 0.35 | E29: 0.35 | F29: 2200 | G29: Editable manufacturing assumption
A30: Groupset | B30: set | C30: 1 | D30: 1 | E30: 1 | F30: 65000 | G30: Exact variant BOM controls selection
A31: Wheelset | B31: set | C31: 1 | D31: 1 | E31: 1 | F31: 35000 | G31: Exact variant BOM controls selection
A32: Tyres | B32: ea | C32: 2 | D32: 2 | E32: 2 | F32: 3500 | G32: Two per bicycle
A33: Cockpit | B33: set | C33: 1 | D33: 1 | E33: 1 | F33: 12000 | G33: Stem/bar or integrated option
A34: Saddle | B34: ea | C34: 1 | D34: 1 | E34: 1 | F34: 4500 | G34: Variant option
A35: Brake system | B35: set | C35: 1 | D35: 1 | E35: 1 | F35: 18000 | G35: Variant option
A36: Packaging kit | B36: kit | C36: 1 | D36: 1 | E36: 1 | F36: 2500 | G36: Shipment-ready packaging
A37: Note | C37: Blue cells are editable assumptions. Quantities are planning estimates, not released purchase orders.
A40: Ramp index | B40: Total bicycles | D40: Capex month | E40: ₹L | F40: Source | G40: Note
A41: 1 | B41: 3 | D41: 3 | E41: 4 | F41: finance/model.ts | G41: CAD/engineering
A42: 2 | B42: 3 | D42: 5 | E42: 8 | F42: finance/model.ts | G42: Development
A43: 3 | B43: 4 | D43: 6 | E43: 6 | F43: finance/model.ts | G43: Validation
A44: 4 | B44: 4 | D44: 7 | E44: 5.5 | F44: finance/model.ts | G44: Pilot preparation
A45: 5 | B45: 5 | D45: 8 | E45: 10 | F45: finance/model.ts | G45: Pre-tooling
A46: 6 | B46: 5 | D46: 10 | E46: 28 | F46: finance/model.ts | G46: Tooling
...

Sheet Monthly Funding
A1: Monthly Fund Requirement
A2: Core funding tranches + optional standby + formula-derived additional funding to preserve cash floor
A5: Month | B5: Date | C5: Units | D5: Opex ₹L | E5: Capex ₹L | F5: Net Procurement Cash ₹L | G5: Planned revenue ₹L | H5: Assumed cash inflow ₹L | I5: Core funding ₹L | J5: Standby ₹L | K5: Opening cash ₹L | L5: Pre-extra cash ₹L | M5: Additional fund required ₹L | N5: Closing cash ₹L
A6: 1 | B6: 46266 | C6: ='Monthly Materials'!C6 | D6: =IF(A6<=Inputs!$B$6-11,2.8,IF(A6<=Inputs!$B$6-6,4.2,IF(A6<=Inputs!$B$6-3,6,IF(A6<=Inputs!$B$6,7.8,9.2)))) | E6: =SUMIF(Inputs!$D$41:$D$46,A6,Inputs!$E$41:$E$46) | F6: =ROUND(INDEX('MRP Cash Bridge'!$J$4:$J$39,A6)/100000,2) | G6: =ROUND('Monthly Materials'!D6*Inputs!$F$5+'Monthly Materials'!E6*Inputs!$F$6+'Monthly Materials'!F6*Inputs!$F$7,2) | H6: =ROUND(G6*Inputs!$B$10,2) | I6: =SUMIFS(Inputs!$C$15:$C$20,Inputs!$B$15:$B$20,A6,Inputs!$D$15:$D$20,"No") | J6: =SUMIFS(Inputs!$C$15:$C$20,Inputs!$B$15:$B$20,A6,Inputs!$D$15:$D$20,"Yes") | K6: =Inputs!$B$11 | L6: =ROUND(K6+H6+I6+J6-D6-E6-F6,2) | M6: =ROUND(MAX(0,Inputs!$B$12-L6),2) | N6: =ROUND(L6+M6,2)
A7: 2 | B7: 46296 | C7: ='Monthly Materials'!C7 | D7: =IF(A7<=Inputs!$B$6-11,2.8,IF(A7<=Inputs!$B$6-6,4.2,IF(A7<=Inputs!$B$6-3,6,IF(A7<=Inputs!$B$6,7.8,9.2)))) | E7: =SUMIF(Inputs!$D$41:$D$46,A7,Inputs!$E$41:$E$46) | F7: =ROUND(INDEX('MRP Cash Bridge'!$J$4:$J$39,A7)/100000,2) | G7: =ROUND('Monthly Materials'!D7*Inputs!$F$5+'Monthly Materials'!E7*Inputs!$F$6+'Monthly Materials'!F7*Inputs!$F$7,2) | H7: =ROUND(G7*Inputs!$B$10,2) | I7: =SUMIFS(Inputs!$C$15:$C$20,Inputs!$B$15:$B$20,A7,Inputs!$D$15:$D$20,"No") | J7: =SUMIFS(Inputs!$C$15:$C$20,Inputs!$B$15:$B$20,A7,Inputs!$D$15:$D$20,"Yes") | K7: =N6 | L7: =ROUND(K7+H7+I7+J7-D7-E7-F7,2) | M7: =ROUND(MAX(0,Inputs!$B$12-L7),2) | N7: =ROUND(L7+M7,2)
A8: 3 | B8: 46327 | C8: ='Monthly Materials'!C8 | D8: =IF(A8<=Inputs!$B$6-11,2.8,IF(A8<=Inputs!$B$6-6,4.2,IF(A8<=Inputs!$B$6-3,6,IF(A8<=Inputs!$B$6,7.8,9.2)))) | E8: =SUMIF(Inputs!$D$41:$D$46,A8,Inputs!$E$41:$E$46) | F8: =ROUND(INDEX('MRP Cash Bridge'!$J$4:$J$39,A8)/100000,2) | G8: =ROUND('Monthly Materials'!D8*Inputs!$F$5+'Monthly Materials'!E8*Inputs!$F$6+'Monthly Materials'!F8*Inputs!$F$7,2) | H8: =ROUND(G8*Inputs!$B$10,2) | I8: =SUMIFS(Inputs!$C$15:$C$20,Inputs!$B$15:$B$20,A8,Inputs!$D$15:$D$20,"No") | J8: =SUMIFS(Inputs!$C$15:$C$20,Inputs!$B$15:$B$20,A8,Inputs!$D$15:$D$20,"Yes") | K8: =N7 | L8: =ROUND(K8+H8+I8+J8-D8-E8-F8,2) | M8: =ROUND(MAX(0,Inputs!$B$12-L8),2) | N8: =ROUND(L8+M8,2)
A9: 4 | B9: 46357 | C9: ='Monthly Materials'!C9 | D9: =IF(A9<=Inputs!$B$6-11,2.8,IF(A9<=Inputs!$B$6-6,4.2,IF(A9<=Inputs!$B$6-3,6,IF(A9<=Inputs!$B$6,7.8,9.2)))) | E9: =SUMIF(Inputs!$D$41:$D$46,A9,Inputs!$E$41:$E$46) | F9: =ROUND(INDEX('MRP Cash Bridge'!$J$4:$J$39,A9)/100000,2) | G9: =ROUND('Monthly Materials'!D9*Inputs!$F$5+'Monthly Materials'!E9*Inputs!$F$6+'Monthly Materials'!F9*Inputs!$F$7,2) | H9: =ROUND(G9*Inputs!$B$10,2) | I9: =SUMIFS(Inputs!$C$15:$C$20,Inputs!$B$15:$B$20,A9,Inputs!$D$15:$D$20,"No") | J9: =SUMIFS(Inputs!$C$15:$C$20,Inputs!$B$15:$B$20,A9,Inputs!$D$15:$D$20,"Yes") | K9: =N8 | L9: =ROUND(K9+H9+I9+J9-D9-E9-F9,2) | M9: =ROUND(MAX(0,Inputs!$B$12-L9),2) | N9: =ROUND(L9+M9,2)
A10: 5 | B10: 46388 | C10: ='Monthly Materials'!C10 | D10: =IF(A10<=Inputs!$B$6-11,2.8,IF(A10<=Inputs!$B$6-6,4.2,IF(A10<=Inputs!$B$6-3,6,IF(A10<=Inputs!$B$6,7.8,9.2)))) | E10: =SUMIF(Inputs!$D$41:$D$46,A10,Inputs!$E$41:$E$46) | F10: =ROUND(INDEX('MRP Cash Bridge'!$J$4:$J$39,A10)/100000,2) | G10: =ROUND('Monthly Materials'!D10*Inputs!$F$5+'Monthly Materials'!E10*Inputs!$F$6+'Monthly Materials'!F10*Inputs!$F$7,2) | H10: =ROUND(G10*Inputs!$B$10,2) | I10: =SUMIFS(Inputs!$C$15:$C$20,Inputs!$B$15:$B$20,A10,Inputs!$D$15:$D$20,"No") | J10: =SUMIFS(Inputs!$C$15:$C$20,Inputs!$B$15:$B$20,A10,Inputs!$D$15:$D$20,"Yes") | K10: =N9 | L10: =ROUND(K10+H10+I10+J10-D10-E10-F10,2) | M10: =ROUND(MAX(0,Inputs!$B$12-L10),2) | N10: =ROUND(L10+M10,2)
A11: 6 | B11: 46419 | C11: ='Monthly Materials'!C11 | D11: =IF(A11<=Inputs!$B$6-11,2.8,IF(A11<=Inputs!$B$6-6,4.2,IF(A11<=Inputs!$B$6-3,6,IF(A11<=Inputs!$B$6,7.8,9.2)))) | E11: =SUMIF(Inputs!$D$41:$D$46,A11,Inputs!$E$41:$E$46) | F11: =ROUND(INDEX('MRP Cash Bridge'!$J$4:$J$39,A11)/100000,2) | G11: =ROUND('Monthly Materials'!D11*Inputs!$F$5+'Monthly Materials'!E11*Inputs!$F$6+'Monthly Materials'!F11*Inputs!$F$7,2) | H11: =ROUND(G11*Inputs!$B$10,2) | I11: =SUMIFS(Inputs!$C$15:$C$20,Inputs!$B$15:$B$20,A11,Inputs!$D$15:$D$20,"No") | J11: =SUMIFS(Inputs!$C$15:$C$20,Inputs!$B$15:$B$20,A11,Inputs!$D$15:$D$20,"Yes") | K11: =N10 | L11: =ROUND(K11+H11+I11+J11-D11-E11-F11,2) | M11: =ROUND(MAX(0,Inputs!$B$12-L11),2) | N11: =ROUND(L11+M11,2)
A12: 7 | B12: 46447 | C12: ='Monthly Materials'!C12 | D12: =IF(A12<=Inputs!$B$6-11,2.8,IF(A12<=Inputs!$B$6-6,4.2,IF(A12<=Inputs!$B$6-3,6,IF(A12<=Inputs!$B$6,7.8,9.2)))) | E12: =SUMIF(Inputs!$D$41:$D$46,A12,Inputs!$E$41:$E$46) | F12: =ROUND(INDEX('MRP Cash Bridge'!$J$4:$J$39,A12)/100000,2) | G12: =ROUND('Monthly Materials'!D12*Inputs!$F$5+'Monthly Materials'!E12*Inputs!$F$6+'Monthly Materials'!F12*Inputs!$F$7,2) | H12: =ROUND(G12*Inputs!$B$10,2) | I12: =SUMIFS(Inputs!$C$15:$C$20,Inputs!$B$15:$B$20,A12,Inputs!$D$15:$D$20,"No") | J12: =SUMIFS(Inputs!$C$15:$C$20,Inputs!$B$15:$B$20,A12,Inputs!$D$15:$D$20,"Yes") | K12: =N11 | L12: =ROUND(K12+H12+I12+J12-D12-E12-F12,2) | M12: =ROUND(MAX(0,Inputs!$B$12-L12),2) | N12: =ROUND(L12+M12,2)
A13: 8 | B13: 46478 | C13: ='Monthly Materials'!C13 | D13: =IF(A13<=Inputs!$B$6-11,2.8,IF(A13<=Inputs!$B$6-6,4.2,IF(A13<=Inputs!$B$6-3,6,IF(A13<=Inputs!$B$6,7.8,9.2)))) | E13: =SUMIF(Inputs!$D$41:$D$46,A13,Inputs!$E$41:$E$46) | F13: =ROUND(INDEX('MRP Cash Bridge'!$J$4:$J$39,A13)/100000,2) | G13: =ROUND('Monthly Materials'!D13*Inputs!$F$5+'Monthly Materials'!E13*Inputs!$F$6+'Monthly Materials'!F13*Inputs!$F$7,2) | H13: =ROUND(G13*Inputs!$B$10,2) | I13: =SUMIFS(Inputs!$C$15:$C$20,Inputs!$B$15:$B$20,A13,Inputs!$D$15:$D$20,"No") | J13: =SUMIFS(Inputs!$C$15:$C$20,Inputs!$B$15:$B$20,A13,Inputs!$D$15:$D$20,"Yes") | K13: =N12 | L13: =ROUND(K13+H13+I13+J13-D13-E13-F13,2) | M13: =ROUND(MAX(0,Inputs!$B$12-L13),2) | N13: =ROUND(L13+M13,2)
A14: 9 | B14: 46508 | C14: ='Monthly Materials'!C14 | D14: =IF(A14<=Inputs!$B$6-11,2.8,IF(A14<=Inputs!$B$6-6,4.2,IF(A14<=Inputs!$B$6-3,6,IF(A14<=Inputs!$B$6,7.8,9.2)))) | E14: =SUMIF(Inputs!$D$41:$D$46,A14,Inputs!$E$41:$E$46) | F14: =ROUND(INDEX('MRP Cash Bridge'!$J$4:$J$39,A14)/100000,2) | G14: =ROUND('Monthly Materials'!D14*Inputs!$F$5+'Monthly Materials'!E14*Inputs!$F$6+'Monthly Materials'!F14*Inputs!$F$7,2) | H14: =ROUND(G14*Inputs!$B$10,2) | I14: =SUMIFS(Inputs!$C$15:$C$20,Inputs!$B$15:$B$20,A14,Inputs!$D$15:$D$20,"No") | J14: =SUMIFS(Inputs!$C$15:$C$20,Inputs!$B$15:$B$20,A14,Inputs!$D$15:$D$20,"Yes") | K14: =N13 | L14: =ROUND(K14+H14+I14+J14-D14-E14-F14,2) | M14: =ROUND(MAX(0,Inputs!$B$12-L14),2) | N14: =ROUND(L14+M14,2)
A15: 10 | B15: 46539 | C15: ='Monthly Materials'!C15 | D15: =IF(A15<=Inputs!$B$6-11,2.8,IF(A15<=Inputs!$B$6-6,4.2,IF(A15<=Inputs!$B$6-3,6,IF(A15<=Inputs!$B$6,7.8,9.2)))) | E15: =SUMIF(Inputs!$D$41:$D$46,A15,Inputs!$E$41:$E$46) | F15: =ROUND(INDEX('MRP Cash Bridge'!$J$4:$J$39,A15)/100000,2) | G15: =ROUND('Monthly Materials'!D15*Inputs!$F$5+'Monthly Materials'!E15*Inputs!$F$6+'Monthly Materials'!F15*Inputs!$F$7,2) | H15: =ROUND(G15*Inputs!$B$10,2) | I15: =SUMIFS(Inputs!$C$15:$C$20,Inputs!$B$15:$B$20,A15,Inputs!$D$15:$D$20,"No") | J15: =SUMIFS(Inputs!$C$15:$C$20,Inputs!$B$15:$B$20,A15,Inputs!$D$15:$D$20,"Yes") | K15: =N14 | L15: =ROUND(K15+H15+I15+J15-D15-E15-F15,2) | M15: =ROUND(MAX(0,Inputs!$B$12-L15),2) | N15: =ROUND(L15+M15,2)
A16: 11 | B16: 46569 | C16: ='Monthly Materials'!C16 | D16: =IF(A16<=Inputs!$B$6-11,2.8,IF(A16<=Inputs!$B$6-6,4.2,IF(A16<=Inputs!$B$6-3,6,IF(A16<=Inputs!$B$6,7.8,9.2)))) | E16: =SUMIF(Inputs!$D$41:$D$46,A16,Inputs!$E$41:$E$46) | F16: =ROUND(INDEX('MRP Cash Bridge'!$J$4:$J$39,A16)/100000,2) | G16: =ROUND('Monthly Materials'!D16*Inputs!$F$5+'Monthly Materials'!E16*Inputs!$F$6+'Monthly Materials'!F16*Inputs!$F$7,2) | H16: =ROUND(G16*Inputs!$B$10,2) | I16: =SUMIFS(Inputs!$C$15:$C$20,Inputs!$B$15:$B$20,A16,Inputs!$D$15:$D$20,"No") | J16: =SUMIFS(Inputs!$C$15:$C$20,Inputs!$B$15:$B$20,A16,Inputs!$D$15:$D$20,"Yes") | K16: =N15 | L16: =ROUND(K16+H16+I16+J16-D16-E16-F16,2) | M16: =ROUND(MAX(0,Inputs!$B$12-L16),2) | N16: =ROUND(L16+M16,2)
A17: 12 | B17: 46600 | C17: ='Monthly Materials'!C17 | D17: =IF(A17<=Inputs!$B$6-11,2.8,IF(A17<=Inputs!$B$6-6,4.2,IF(A17<=Inputs!$B$6-3,6,IF(A17<=Inputs!$B$6,7.8,9.2)))) | E17: =SUMIF(Inputs!$D$41:$D$46,A17,Inputs!$E$41:$E$46) | F17: =ROUND(INDEX('MRP Cash Bridge'!$J$4:$J$39,A17)/100000,2) | G17: =ROUND('Monthly Materials'!D17*Inputs!$F$5+'Monthly Materials'!E17*Inputs!$F$6+'Monthly Materials'!F17*Inputs!$F$7,2) | H17: =ROUND(G17*Inputs!$B$10,2) | I17: =SUMIFS(Inputs!$C$15:$C$20,Inputs!$B$15:$B$20,A17,Inputs!$D$15:$D$20,"No") | J17: =SUMIFS(Inputs!$C$15:$C$20,Inputs!$B$15:$B$20,A17,Inputs!$D$15:$D$20,"Yes") | K17: =N16 | L17: =ROUND(K17+H17+I17+J17-D17-E17-F17,2) | M17: =ROUND(MAX(0,Inputs!$B$12-L17),2) | N17: =ROUND(L17+M17,2)
A18: 13 | B18: 46631 | C18: ='Monthly Materials'!C18 | D18: =IF(A18<=Inputs!$B$6-11,2.8,IF(A18<=Inputs!$B$6-6,4.2,IF(A18<=Inputs!$B$6-3,6,IF(A18<=Inputs!$B$6,7.8,9.2)))) | E18: =SUMIF(Inputs!$D$41:$D$46,A18,Inputs!$E$41:$E$46) | F18: =ROUND(INDEX('MRP Cash Bridge'!$J$4:$J$39,A18)/100000,2) | G18: =ROUND('Monthly Materials'!D18*Inputs!$F$5+'Monthly Materials'!E18*Inputs!$F$6+'Monthly Materials'!F18*Inputs!$F$7,2) | H18: =ROUND(G18*Inputs!$B$10,2) | I18: =SUMIFS(Inputs!$C$15:$C$20,Inputs!$B$15:$B$20,A18,Inputs!$D$15:$D$20,"No") | J18: =SUMIFS(Inputs!$C$15:$C$20,Inputs!$B$15:$B$20,A18,Inputs!$D$15:$D$20,"Yes") | K18: =N17 | L18: =ROUND(K18+H18+I18+J18-D18-E18-F18,2) | M18: =ROUND(MAX(0,Inputs!$B$12-L18),2) | N18: =ROUND(L18+M18,2)
... A41: 36 | B41: 47331 | C41: ='Monthly Materials'!C41 | D41: =IF(A41<=Inputs!$B$6-11,2.8,IF(A41<=Inputs!$B$6-6,4.2,IF(A41<=Inputs!$B$6-3,6,IF(A41<=Inputs!$B$6,7.8,9.2)))) | E41: =SUMIF(Inputs!$D$41:$D$46,A41,Inputs!$E$41:$E$46) | F41: =ROUND(INDEX('MRP Cash Bridge'!$J$4:$J$39,A41)/100000,2) | G41: =ROUND('Monthly Materials'!D41*Inputs!$F$5+'Monthly Materials'!E41*Inputs!$F$6+'Monthly Materials'!F41*Inputs!$F$7,2) | H41: =ROUND(G41*Inputs!$B$10,2) | I41: =SUMIFS(Inputs!$C$15:$C$20,Inputs!$B$15:$B$20,A41,Inputs!$D$15:$D$20,"No") | J41: =SUMIFS(Inputs!$C$15:$C$20,Inputs!$B$15:$B$20,A41,Inputs!$D$15:$D$20,"Yes") | K41: =N40 | L41: =ROUND(K41+H41+I41+J41-D41-E41-F41,2) | M41: =ROUND(MAX(0,Inputs!$B$12-L41),2) | N41: =ROUND(L41+M41,2)
A42: 36M TOTAL | C42: =SUM(C6:C41) | D42: =SUM(D6:D41) | E42: =SUM(E6:E41) | F42: =SUM(F6:F41) | G42: =SUM(G6:G41) | H42: =SUM(H6:H41) | I42: =SUM(I6:I41) | J42: =SUM(J6:J41) | M42: =SUM(M6:M41) | N42: =N41

Sheet Monthly Materials
A1: Monthly Raw Materials & Components
A2: Gross requirement including editable material buffer · opening inventory assumed zero
A5: Month | B5: Date | C5: Total units | D5: Longitude | E5: Latitude | F5: Altitude | G5: Aluminium/OEM frameset (set) | H5: T700 prepreg (kg) | I5: T800 prepreg (kg) | J5: Resin & bonding system (kg) | K5: Paint & clear coat (L) | L5: Groupset (set) | M5: Wheelset (set) | N5: Tyres (ea) | O5: Cockpit (set) | P5: Saddle (ea) | Q5: Brake system (set) | R5: Packaging kit (kit) | S5: Material cost ₹ | T5: Material cost ₹L
A6: 1 | B6: 46266 | C6: =IF(A6<Inputs!$B$6,0,INDEX(Inputs!$B$41:$B$64,MIN(A6-Inputs!$B$6+1,24))*Inputs!$B$8) | D6: =IF(C6=0,0,IF(A6<Inputs!$G$7,ROUND(C6*25%,0),ROUND(C6*Inputs!$E$5,0))) | E6: =IF(C6=0,0,IF(A6<Inputs!$G$7,C6-D6,ROUND(C6*Inputs!$E$6,0))) | F6: =C6-D6-E6 | G6: =ROUND((D6*Inputs!$C$25+E6*Inputs!$D$25+F6*Inputs!$E$25)*(1+Inputs!$B$9),2) | H6: =ROUND((D6*Inputs!$C$26+E6*Inputs!$D$26+F6*Inputs!$E$26)*(1+Inputs!$B$9),2) | I6: =ROUND((D6*Inputs!$C$27+E6*Inputs!$D$27+F6*Inputs!$E$27)*(1+Inputs!$B$9),2) | J6: =ROUND((D6*Inputs!$C$28+E6*Inputs!$D$28+F6*Inputs!$E$28)*(1+Inputs!$B$9),2) | K6: =ROUND((D6*Inputs!$C$29+E6*Inputs!$D$29+F6*Inputs!$E$29)*(1+Inputs!$B$9),2) | L6: =ROUND((D6*Inputs!$C$30+E6*Inputs!$D$30+F6*Inputs!$E$30)*(1+Inputs!$B$9),2) | M6: =ROUND((D6*Inputs!$C$31+E6*Inputs!$D$31+F6*Inputs!$E$31)*(1+Inputs!$B$9),2) | N6: =ROUND((D6*Inputs!$C$32+E6*Inputs!$D$32+F6*Inputs!$E$32)*(1+Inputs!$B$9),2) | O6: =ROUND((D6*Inputs!$C$33+E6*Inputs!$D$33+F6*Inputs!$E$33)*(1+Inputs!$B$9),2) | P6: =ROUND((D6*Inputs!$C$34+E6*Inputs!$D$34+F6*Inputs!$E$34)*(1+Inputs!$B$9),2) | Q6: =ROUND((D6*Inputs!$C$35+E6*Inputs!$D$35+F6*Inputs!$E$35)*(1+Inputs!$B$9),2) | R6: =ROUND((D6*Inputs!$C$36+E6*Inputs!$D$36+F6*Inputs!$E$36)*(1+Inputs!$B$9),2) | S6: =ROUND(G6*Inputs!$F$25+H6*Inputs!$F$26+I6*Inputs!$F$27+J6*Inputs!$F$28+K6*Inputs!$F$29+L6*Inputs!$F$30+M6*Inputs!$F$31+N6*Inputs!$F$32+O6*Inputs!$F$33+P6*Inputs!$F$34+Q6*Inputs!$F$35+R6*Inputs!$F$36,2) | T6: =ROUND(S6/100000,2)
A7: 2 | B7: 46296 | C7: =IF(A7<Inputs!$B$6,0,INDEX(Inputs!$B$41:$B$64,MIN(A7-Inputs!$B$6+1,24))*Inputs!$B$8) | D7: =IF(C7=0,0,IF(A7<Inputs!$G$7,ROUND(C7*25%,0),ROUND(C7*Inputs!$E$5,0))) | E7: =IF(C7=0,0,IF(A7<Inputs!$G$7,C7-D7,ROUND(C7*Inputs!$E$6,0))) | F7: =C7-D7-E7 | G7: =ROUND((D7*Inputs!$C$25+E7*Inputs!$D$25+F7*Inputs!$E$25)*(1+Inputs!$B$9),2) | H7: =ROUND((D7*Inputs!$C$26+E7*Inputs!$D$26+F7*Inputs!$E$26)*(1+Inputs!$B$9),2) | I7: =ROUND((D7*Inputs!$C$27+E7*Inputs!$D$27+F7*Inputs!$E$27)*(1+Inputs!$B$9),2) | J7: =ROUND((D7*Inputs!$C$28+E7*Inputs!$D$28+F7*Inputs!$E$28)*(1+Inputs!$B$9),2) | K7: =ROUND((D7*Inputs!$C$29+E7*Inputs!$D$29+F7*Inputs!$E$29)*(1+Inputs!$B$9),2) | L7: =ROUND((D7*Inputs!$C$30+E7*Inputs!$D$30+F7*Inputs!$E$30)*(1+Inputs!$B$9),2) | M7: =ROUND((D7*Inputs!$C$31+E7*Inputs!$D$31+F7*Inputs!$E$31)*(1+Inputs!$B$9),2) | N7: =ROUND((D7*Inputs!$C$32+E7*Inputs!$D$32+F7*Inputs!$E$32)*(1+Inputs!$B$9),2) | O7: =ROUND((D7*Inputs!$C$33+E7*Inputs!$D$33+F7*Inputs!$E$33)*(1+Inputs!$B$9),2) | P7: =ROUND((D7*Inputs!$C$34+E7*Inputs!$D$34+F7*Inputs!$E$34)*(1+Inputs!$B$9),2) | Q7: =ROUND((D7*Inputs!$C$35+E7*Inputs!$D$35+F7*Inputs!$E$35)*(1+Inputs!$B$9),2) | R7: =ROUND((D7*Inputs!$C$36+E7*Inputs!$D$36+F7*Inputs!$E$36)*(1+Inputs!$B$9),2) | S7: =ROUND(G7*Inputs!$F$25+H7*Inputs!$F$26+I7*Inputs!$F$27+J7*Inputs!$F$28+K7*Inputs!$F$29+L7*Inputs!$F$30+M7*Inputs!$F$31+N7*Inputs!$F$32+O7*Inputs!$F$33+P7*Inputs!$F$34+Q7*Inputs!$F$35+R7*Inputs!$F$36,2) | T7: =ROUND(S7/100000,2)
A8: 3 | B8: 46327 | C8: =IF(A8<Inputs!$B$6,0,INDEX(Inputs!$B$41:$B$64,MIN(A8-Inputs!$B$6+1,24))*Inputs!$B$8) | D8: =IF(C8=0,0,IF(A8<Inputs!$G$7,ROUND(C8*25%,0),ROUND(C8*Inputs!$E$5,0))) | E8: =IF(C8=0,0,IF(A8<Inputs!$G$7,C8-D8,ROUND(C8*Inputs!$E$6,0))) | F8: =C8-D8-E8 | G8: =ROUND((D8*Inputs!$C$25+E8*Inputs!$D$25+F8*Inputs!$E$25)*(1+Inputs!$B$9),2) | H8: =ROUND((D8*Inputs!$C$26+E8*Inputs!$D$26+F8*Inputs!$E$26)*(1+Inputs!$B$9),2) | I8: =ROUND((D8*Inputs!$C$27+E8*Inputs!$D$27+F8*Inputs!$E$27)*(1+Inputs!$B$9),2) | J8: =ROUND((D8*Inputs!$C$28+E8*Inputs!$D$28+F8*Inputs!$E$28)*(1+Inputs!$B$9),2) | K8: =ROUND((D8*Inputs!$C$29+E8*Inputs!$D$29+F8*Inputs!$E$29)*(1+Inputs!$B$9),2) | L8: =ROUND((D8*Inputs!$C$30+E8*Inputs!$D$30+F8*Inputs!$E$30)*(1+Inputs!$B$9),2) | M8: =ROUND((D8*Inputs!$C$31+E8*Inputs!$D$31+F8*Inputs!$E$31)*(1+Inputs!$B$9),2) | N8: =ROUND((D8*Inputs!$C$32+E8*Inputs!$D$32+F8*Inputs!$E$32)*(1+Inputs!$B$9),2) | O8: =ROUND((D8*Inputs!$C$33+E8*Inputs!$D$33+F8*Inputs!$E$33)*(1+Inputs!$B$9),2) | P8: =ROUND((D8*Inputs!$C$34+E8*Inputs!$D$34+F8*Inputs!$E$34)*(1+Inputs!$B$9),2) | Q8: =ROUND((D8*Inputs!$C$35+E8*Inputs!$D$35+F8*Inputs!$E$35)*(1+Inputs!$B$9),2) | R8: =ROUND((D8*Inputs!$C$36+E8*Inputs!$D$36+F8*Inputs!$E$36)*(1+Inputs!$B$9),2) | S8: =ROUND(G8*Inputs!$F$25+H8*Inputs!$F$26+I8*Inputs!$F$27+J8*Inputs!$F$28+K8*Inputs!$F$29+L8*Inputs!$F$30+M8*Inputs!$F$31+N8*Inputs!$F$32+O8*Inputs!$F$33+P8*Inputs!$F$34+Q8*Inputs!$F$35+R8*Inputs!$F$36,2) | T8: =ROUND(S8/100000,2)
A9: 4 | B9: 46357 | C9: =IF(A9<Inputs!$B$6,0,INDEX(Inputs!$B$41:$B$64,MIN(A9-Inputs!$B$6+1,24))*Inputs!$B$8) | D9: =IF(C9=0,0,IF(A9<Inputs!$G$7,ROUND(C9*25%,0),ROUND(C9*Inputs!$E$5,0))) | E9: =IF(C9=0,0,IF(A9<Inputs!$G$7,C9-D9,ROUND(C9*Inputs!$E$6,0))) | F9: =C9-D9-E9 | G9: =ROUND((D9*Inputs!$C$25+E9*Inputs!$D$25+F9*Inputs!$E$25)*(1+Inputs!$B$9),2) | H9: =ROUND((D9*Inputs!$C$26+E9*Inputs!$D$26+F9*Inputs!$E$26)*(1+Inputs!$B$9),2) | I9: =ROUND((D9*Inputs!$C$27+E9*Inputs!$D$27+F9*Inputs!$E$27)*(1+Inputs!$B$9),2) | J9: =ROUND((D9*Inputs!$C$28+E9*Inputs!$D$28+F9*Inputs!$E$28)*(1+Inputs!$B$9),2) | K9: =ROUND((D9*Inputs!$C$29+E9*Inputs!$D$29+F9*Inputs!$E$29)*(1+Inputs!$B$9),2) | L9: =ROUND((D9*Inputs!$C$30+E9*Inputs!$D$30+F9*Inputs!$E$30)*(1+Inputs!$B$9),2) | M9: =ROUND((D9*Inputs!$C$31+E9*Inputs!$D$31+F9*Inputs!$E$31)*(1+Inputs!$B$9),2) | N9: =ROUND((D9*Inputs!$C$32+E9*Inputs!$D$32+F9*Inputs!$E$32)*(1+Inputs!$B$9),2) | O9: =ROUND((D9*Inputs!$C$33+E9*Inputs!$D$33+F9*Inputs!$E$33)*(1+Inputs!$B$9),2) | P9: =ROUND((D9*Inputs!$C$34+E9*Inputs!$D$34+F9*Inputs!$E$34)*(1+Inputs!$B$9),2) | Q9: =ROUND((D9*Inputs!$C$35+E9*Inputs!$D$35+F9*Inputs!$E$35)*(1+Inputs!$B$9),2) | R9: =ROUND((D9*Inputs!$C$36+E9*Inputs!$D$36+F9*Inputs!$E$36)*(1+Inputs!$B$9),2) | S9: =ROUND(G9*Inputs!$F$25+H9*Inputs!$F$26+I9*Inputs!$F$27+J9*Inputs!$F$28+K9*Inputs!$F$29+L9*Inputs!$F$30+M9*Inputs!$F$31+N9*Inputs!$F$32+O9*Inputs!$F$33+P9*Inputs!$F$34+Q9*Inputs!$F$35+R9*Inputs!$F$36,2) | T9: =ROUND(S9/100000,2)
A10: 5 | B10: 46388 | C10: =IF(A10<Inputs!$B$6,0,INDEX(Inputs!$B$41:$B$64,MIN(A10-Inputs!$B$6+1,24))*Inputs!$B$8) | D10: =IF(C10=0,0,IF(A10<Inputs!$G$7,ROUND(C10*25%,0),ROUND(C10*Inputs!$E$5,0))) | E10: =IF(C10=0,0,IF(A10<Inputs!$G$7,C10-D10,ROUND(C10*Inputs!$E$6,0))) | F10: =C10-D10-E10 | G10: =ROUND((D10*Inputs!$C$25+E10*Inputs!$D$25+F10*Inputs!$E$25)*(1+Inputs!$B$9),2) | H10: =ROUND((D10*Inputs!$C$26+E10*Inputs!$D$26+F10*Inputs!$E$26)*(1+Inputs!$B$9),2) | I10: =ROUND((D10*Inputs!$C$27+E10*Inputs!$D$27+F10*Inputs!$E$27)*(1+Inputs!$B$9),2) | J10: =ROUND((D10*Inputs!$C$28+E10*Inputs!$D$28+F10*Inputs!$E$28)*(1+Inputs!$B$9),2) | K10: =ROUND((D10*Inputs!$C$29+E10*Inputs!$D$29+F10*Inputs!$E$29)*(1+Inputs!$B$9),2) | L10: =ROUND((D10*Inputs!$C$30+E10*Inputs!$D$30+F10*Inputs!$E$30)*(1+Inputs!$B$9),2) | M10: =ROUND((D10*Inputs!$C$31+E10*Inputs!$D$31+F10*Inputs!$E$31)*(1+Inputs!$B$9),2) | N10: =ROUND((D10*Inputs!$C$32+E10*Inputs!$D$32+F10*Inputs!$E$32)*(1+Inputs!$B$9),2) | O10: =ROUND((D10*Inputs!$C$33+E10*Inputs!$D$33+F10*Inputs!$E$33)*(1+Inputs!$B$9),2) | P10: =ROUND((D10*Inputs!$C$34+E10*Inputs!$D$34+F10*Inputs!$E$34)*(1+Inputs!$B$9),2) | Q10: =ROUND((D10*Inputs!$C$35+E10*Inputs!$D$35+F10*Inputs!$E$35)*(1+Inputs!$B$9),2) | R10: =ROUND((D10*Inputs!$C$36+E10*Inputs!$D$36+F10*Inputs!$E$36)*(1+Inputs!$B$9),2) | S10: =ROUND(G10*Inputs!$F$25+H10*Inputs!$F$26+I10*Inputs!$F$27+J10*Inputs!$F$28+K10*Inputs!$F$29+L10*Inputs!$F$30+M10*Inputs!$F$31+N10*Inputs!$F$32+O10*Inputs!$F$33+P10*Inputs!$F$34+Q10*Inputs!$F$35+R10*Inputs!$F$36,2) | T10: =ROUND(S10/100000,2)
A11: 6 | B11: 46419 | C11: =IF(A11<Inputs!$B$6,0,INDEX(Inputs!$B$41:$B$64,MIN(A11-Inputs!$B$6+1,24))*Inputs!$B$8) | D11: =IF(C11=0,0,IF(A11<Inputs!$G$7,ROUND(C11*25%,0),ROUND(C11*Inputs!$E$5,0))) | E11: =IF(C11=0,0,IF(A11<Inputs!$G$7,C11-D11,ROUND(C11*Inputs!$E$6,0))) | F11: =C11-D11-E11 | G11: =ROUND((D11*Inputs!$C$25+E11*Inputs!$D$25+F11*Inputs!$E$25)*(1+Inputs!$B$9),2) | H11: =ROUND((D11*Inputs!$C$26+E11*Inputs!$D$26+F11*Inputs!$E$26)*(1+Inputs!$B$9),2) | I11: =ROUND((D11*Inputs!$C$27+E11*Inputs!$D$27+F11*Inputs!$E$27)*(1+Inputs!$B$9),2) | J11: =ROUND((D11*Inputs!$C$28+E11*Inputs!$D$28+F11*Inputs!$E$28)*(1+Inputs!$B$9),2) | K11: =ROUND((D11*Inputs!$C$29+E11*Inputs!$D$29+F11*Inputs!$E$29)*(1+Inputs!$B$9),2) | L11: =ROUND((D11*Inputs!$C$30+E11*Inputs!$D$30+F11*Inputs!$E$30)*(1+Inputs!$B$9),2) | M11: =ROUND((D11*Inputs!$C$31+E11*Inputs!$D$31+F11*Inputs!$E$31)*(1+Inputs!$B$9),2) | N11: =ROUND((D11*Inputs!$C$32+E11*Inputs!$D$32+F11*Inputs!$E$32)*(1+Inputs!$B$9),2) | O11: =ROUND((D11*Inputs!$C$33+E11*Inputs!$D$33+F11*Inputs!$E$33)*(1+Inputs!$B$9),2) | P11: =ROUND((D11*Inputs!$C$34+E11*Inputs!$D$34+F11*Inputs!$E$34)*(1+Inputs!$B$9),2) | Q11: =ROUND((D11*Inputs!$C$35+E11*Inputs!$D$35+F11*Inputs!$E$35)*(1+Inputs!$B$9),2) | R11: =ROUND((D11*Inputs!$C$36+E11*Inputs!$D$36+F11*Inputs!$E$36)*(1+Inputs!$B$9),2) | S11: =ROUND(G11*Inputs!$F$25+H11*Inputs!$F$26+I11*Inputs!$F$27+J11*Inputs!$F$28+K11*Inputs!$F$29+L11*Inputs!$F$30+M11*Inputs!$F$31+N11*Inputs!$F$32+O11*Inputs!$F$33+P11*Inputs!$F$34+Q11*Inputs!$F$35+R11*Inputs!$F$36,2) | T11: =ROUND(S11/100000,2)
A12: 7 | B12: 46447 | C12: =IF(A12<Inputs!$B$6,0,INDEX(Inputs!$B$41:$B$64,MIN(A12-Inputs!$B$6+1,24))*Inputs!$B$8) | D12: =IF(C12=0,0,IF(A12<Inputs!$G$7,ROUND(C12*25%,0),ROUND(C12*Inputs!$E$5,0))) | E12: =IF(C12=0,0,IF(A12<Inputs!$G$7,C12-D12,ROUND(C12*Inputs!$E$6,0))) | F12: =C12-D12-E12 | G12: =ROUND((D12*Inputs!$C$25+E12*Inputs!$D$25+F12*Inputs!$E$25)*(1+Inputs!$B$9),2) | H12: =ROUND((D12*Inputs!$C$26+E12*Inputs!$D$26+F12*Inputs!$E$26)*(1+Inputs!$B$9),2) | I12: =ROUND((D12*Inputs!$C$27+E12*Inputs!$D$27+F12*Inputs!$E$27)*(1+Inputs!$B$9),2) | J12: =ROUND((D12*Inputs!$C$28+E12*Inputs!$D$28+F12*Inputs!$E$28)*(1+Inputs!$B$9),2) | K12: =ROUND((D12*Inputs!$C$29+E12*Inputs!$D$29+F12*Inputs!$E$29)*(1+Inputs!$B$9),2) | L12: =ROUND((D12*Inputs!$C$30+E12*Inputs!$D$30+F12*Inputs!$E$30)*(1+Inputs!$B$9),2) | M12: =ROUND((D12*Inputs!$C$31+E12*Inputs!$D$31+F12*Inputs!$E$31)*(1+Inputs!$B$9),2) | N12: =ROUND((D12*Inputs!$C$32+E12*Inputs!$D$32+F12*Inputs!$E$32)*(1+Inputs!$B$9),2) | O12: =ROUND((D12*Inputs!$C$33+E12*Inputs!$D$33+F12*Inputs!$E$33)*(1+Inputs!$B$9),2) | P12: =ROUND((D12*Inputs!$C$34+E12*Inputs!$D$34+F12*Inputs!$E$34)*(1+Inputs!$B$9),2) | Q12: =ROUND((D12*Inputs!$C$35+E12*Inputs!$D$35+F12*Inputs!$E$35)*(1+Inputs!$B$9),2) | R12: =ROUND((D12*Inputs!$C$36+E12*Inputs!$D$36+F12*Inputs!$E$36)*(1+Inputs!$B$9),2) | S12: =ROUND(G12*Inputs!$F$25+H12*Inputs!$F$26+I12*Inputs!$F$27+J12*Inputs!$F$28+K12*Inputs!$F$29+L12*Inputs!$F$30+M12*Inputs!$F$31+N12*Inputs!$F$32+O12*Inputs!$F$33+P12*Inputs!$F$34+Q12*Inputs!$F$35+R12*Inputs!$F$36,2) | T12: =ROUND(S12/100000,2)
A13: 8 | B13: 46478 | C13: =IF(A13<Inputs!$B$6,0,INDEX(Inputs!$B$41:$B$64,MIN(A13-Inputs!$B$6+1,24))*Inputs!$B$8) | D13: =IF(C13=0,0,IF(A13<Inputs!$G$7,ROUND(C13*25%,0),ROUND(C13*Inputs!$E$5,0))) | E13: =IF(C13=0,0,IF(A13<Inputs!$G$7,C13-D13,ROUND(C13*Inputs!$E$6,0))) | F13: =C13-D13-E13 | G13: =ROUND((D13*Inputs!$C$25+E13*Inputs!$D$25+F13*Inputs!$E$25)*(1+Inputs!$B$9),2) | H13: =ROUND((D13*Inputs!$C$26+E13*Inputs!$D$26+F13*Inputs!$E$26)*(1+Inputs!$B$9),2) | I13: =ROUND((D13*Inputs!$C$27+E13*Inputs!$D$27+F13*Inputs!$E$27)*(1+Inputs!$B$9),2) | J13: =ROUND((D13*Inputs!$C$28+E13*Inputs!$D$28+F13*Inputs!$E$28)*(1+Inputs!$B$9),2) | K13: =ROUND((D13*Inputs!$C$29+E13*Inputs!$D$29+F13*Inputs!$E$29)*(1+Inputs!$B$9),2) | L13: =ROUND((D13*Inputs!$C$30+E13*Inputs!$D$30+F13*Inputs!$E$30)*(1+Inputs!$B$9),2) | M13: =ROUND((D13*Inputs!$C$31+E13*Inputs!$D$31+F13*Inputs!$E$31)*(1+Inputs!$B$9),2) | N13: =ROUND((D13*Inputs!$C$32+E13*Inputs!$D$32+F13*Inputs!$E$32)*(1+Inputs!$B$9),2) | O13: =ROUND((D13*Inputs!$C$33+E13*Inputs!$D$33+F13*Inputs!$E$33)*(1+Inputs!$B$9),2) | P13: =ROUND((D13*Inputs!$C$34+E13*Inputs!$D$34+F13*Inputs!$E$34)*(1+Inputs!$B$9),2) | Q13: =ROUND((D13*Inputs!$C$35+E13*Inputs!$D$35+F13*Inputs!$E$35)*(1+Inputs!$B$9),2) | R13: =ROUND((D13*Inputs!$C$36+E13*Inputs!$D$36+F13*Inputs!$E$36)*(1+Inputs!$B$9),2) | S13: =ROUND(G13*Inputs!$F$25+H13*Inputs!$F$26+I13*Inputs!$F$27+J13*Inputs!$F$28+K13*Inputs!$F$29+L13*Inputs!$F$30+M13*Inputs!$F$31+N13*Inputs!$F$32+O13*Inputs!$F$33+P13*Inputs!$F$34+Q13*Inputs!$F$35+R13*Inputs!$F$36,2) | T13: =ROUND(S13/100000,2)
A14: 9 | B14: 46508 | C14: =IF(A14<Inputs!$B$6,0,INDEX(Inputs!$B$41:$B$64,MIN(A14-Inputs!$B$6+1,24))*Inputs!$B$8) | D14: =IF(C14=0,0,IF(A14<Inputs!$G$7,ROUND(C14*25%,0),ROUND(C14*Inputs!$E$5,0))) | E14: =IF(C14=0,0,IF(A14<Inputs!$G$7,C14-D14,ROUND(C14*Inputs!$E$6,0))) | F14: =C14-D14-E14 | G14: =ROUND((D14*Inputs!$C$25+E14*Inputs!$D$25+F14*Inputs!$E$25)*(1+Inputs!$B$9),2) | H14: =ROUND((D14*Inputs!$C$26+E14*Inputs!$D$26+F14*Inputs!$E$26)*(1+Inputs!$B$9),2) | I14: =ROUND((D14*Inputs!$C$27+E14*Inputs!$D$27+F14*Inputs!$E$27)*(1+Inputs!$B$9),2) | J14: =ROUND((D14*Inputs!$C$28+E14*Inputs!$D$28+F14*Inputs!$E$28)*(1+Inputs!$B$9),2) | K14: =ROUND((D14*Inputs!$C$29+E14*Inputs!$D$29+F14*Inputs!$E$29)*(1+Inputs!$B$9),2) | L14: =ROUND((D14*Inputs!$C$30+E14*Inputs!$D$30+F14*Inputs!$E$30)*(1+Inputs!$B$9),2) | M14: =ROUND((D14*Inputs!$C$31+E14*Inputs!$D$31+F14*Inputs!$E$31)*(1+Inputs!$B$9),2) | N14: =ROUND((D14*Inputs!$C$32+E14*Inputs!$D$32+F14*Inputs!$E$32)*(1+Inputs!$B$9),2) | O14: =ROUND((D14*Inputs!$C$33+E14*Inputs!$D$33+F14*Inputs!$E$33)*(1+Inputs!$B$9),2) | P14: =ROUND((D14*Inputs!$C$34+E14*Inputs!$D$34+F14*Inputs!$E$34)*(1+Inputs!$B$9),2) | Q14: =ROUND((D14*Inputs!$C$35+E14*Inputs!$D$35+F14*Inputs!$E$35)*(1+Inputs!$B$9),2) | R14: =ROUND((D14*Inputs!$C$36+E14*Inputs!$D$36+F14*Inputs!$E$36)*(1+Inputs!$B$9),2) | S14: =ROUND(G14*Inputs!$F$25+H14*Inputs!$F$26+I14*Inputs!$F$27+J14*Inputs!$F$28+K14*Inputs!$F$29+L14*Inputs!$F$30+M14*Inputs!$F$31+N14*Inputs!$F$32+O14*Inputs!$F$33+P14*Inputs!$F$34+Q14*Inputs!$F$35+R14*Inputs!$F$36,2) | T14: =ROUND(S14/100000,2)
A15: 10 | B15: 46539 | C15: =IF(A15<Inputs!$B$6,0,INDEX(Inputs!$B$41:$B$64,MIN(A15-Inputs!$B$6+1,24))*Inputs!$B$8) | D15: =IF(C15=0,0,IF(A15<Inputs!$G$7,ROUND(C15*25%,0),ROUND(C15*Inputs!$E$5,0))) | E15: =IF(C15=0,0,IF(A15<Inputs!$G$7,C15-D15,ROUND(C15*Inputs!$E$6,0))) | F15: =C15-D15-E15 | G15: =ROUND((D15*Inputs!$C$25+E15*Inputs!$D$25+F15*Inputs!$E$25)*(1+Inputs!$B$9),2) | H15: =ROUND((D15*Inputs!$C$26+E15*Inputs!$D$26+F15*Inputs!$E$26)*(1+Inputs!$B$9),2) | I15: =ROUND((D15*Inputs!$C$27+E15*Inputs!$D$27+F15*Inputs!$E$27)*(1+Inputs!$B$9),2) | J15: =ROUND((D15*Inputs!$C$28+E15*Inputs!$D$28+F15*Inputs!$E$28)*(1+Inputs!$B$9),2) | K15: =ROUND((D15*Inputs!$C$29+E15*Inputs!$D$29+F15*Inputs!$E$29)*(1+Inputs!$B$9),2) | L15: =ROUND((D15*Inputs!$C$30+E15*Inputs!$D$30+F15*Inputs!$E$30)*(1+Inputs!$B$9),2) | M15: =ROUND((D15*Inputs!$C$31+E15*Inputs!$D$31+F15*Inputs!$E$31)*(1+Inputs!$B$9),2) | N15: =ROUND((D15*Inputs!$C$32+E15*Inputs!$D$32+F15*Inputs!$E$32)*(1+Inputs!$B$9),2) | O15: =ROUND((D15*Inputs!$C$33+E15*Inputs!$D$33+F15*Inputs!$E$33)*(1+Inputs!$B$9),2) | P15: =ROUND((D15*Inputs!$C$34+E15*Inputs!$D$34+F15*Inputs!$E$34)*(1+Inputs!$B$9),2) | Q15: =ROUND((D15*Inputs!$C$35+E15*Inputs!$D$35+F15*Inputs!$E$35)*(1+Inputs!$B$9),2) | R15: =ROUND((D15*Inputs!$C$36+E15*Inputs!$D$36+F15*Inputs!$E$36)*(1+Inputs!$B$9),2) | S15: =ROUND(G15*Inputs!$F$25+H15*Inputs!$F$26+I15*Inputs!$F$27+J15*Inputs!$F$28+K15*Inputs!$F$29+L15*Inputs!$F$30+M15*Inputs!$F$31+N15*Inputs!$F$32+O15*Inputs!$F$33+P15*Inputs!$F$34+Q15*Inputs!$F$35+R15*Inputs!$F$36,2) | T15: =ROUND(S15/100000,2)
A16: 11 | B16: 46569 | C16: =IF(A16<Inputs!$B$6,0,INDEX(Inputs!$B$41:$B$64,MIN(A16-Inputs!$B$6+1,24))*Inputs!$B$8) | D16: =IF(C16=0,0,IF(A16<Inputs!$G$7,ROUND(C16*25%,0),ROUND(C16*Inputs!$E$5,0))) | E16: =IF(C16=0,0,IF(A16<Inputs!$G$7,C16-D16,ROUND(C16*Inputs!$E$6,0))) | F16: =C16-D16-E16 | G16: =ROUND((D16*Inputs!$C$25+E16*Inputs!$D$25+F16*Inputs!$E$25)*(1+Inputs!$B$9),2) | H16: =ROUND((D16*Inputs!$C$26+E16*Inputs!$D$26+F16*Inputs!$E$26)*(1+Inputs!$B$9),2) | I16: =ROUND((D16*Inputs!$C$27+E16*Inputs!$D$27+F16*Inputs!$E$27)*(1+Inputs!$B$9),2) | J16: =ROUND((D16*Inputs!$C$28+E16*Inputs!$D$28+F16*Inputs!$E$28)*(1+Inputs!$B$9),2) | K16: =ROUND((D16*Inputs!$C$29+E16*Inputs!$D$29+F16*Inputs!$E$29)*(1+Inputs!$B$9),2) | L16: =ROUND((D16*Inputs!$C$30+E16*Inputs!$D$30+F16*Inputs!$E$30)*(1+Inputs!$B$9),2) | M16: =ROUND((D16*Inputs!$C$31+E16*Inputs!$D$31+F16*Inputs!$E$31)*(1+Inputs!$B$9),2) | N16: =ROUND((D16*Inputs!$C$32+E16*Inputs!$D$32+F16*Inputs!$E$32)*(1+Inputs!$B$9),2) | O16: =ROUND((D16*Inputs!$C$33+E16*Inputs!$D$33+F16*Inputs!$E$33)*(1+Inputs!$B$9),2) | P16: =ROUND((D16*Inputs!$C$34+E16*Inputs!$D$34+F16*Inputs!$E$34)*(1+Inputs!$B$9),2) | Q16: =ROUND((D16*Inputs!$C$35+E16*Inputs!$D$35+F16*Inputs!$E$35)*(1+Inputs!$B$9),2) | R16: =ROUND((D16*Inputs!$C$36+E16*Inputs!$D$36+F16*Inputs!$E$36)*(1+Inputs!$B$9),2) | S16: =ROUND(G16*Inputs!$F$25+H16*Inputs!$F$26+I16*Inputs!$F$27+J16*Inputs!$F$28+K16*Inputs!$F$29+L16*Inputs!$F$30+M16*Inputs!$F$31+N16*Inputs!$F$32+O16*Inputs!$F$33+P16*Inputs!$F$34+Q16*Inputs!$F$35+R16*Inputs!$F$36,2) | T16: =ROUND(S16/100000,2)
A17: 12 | B17: 46600 | C17: =IF(A17<Inputs!$B$6,0,INDEX(Inputs!$B$41:$B$64,MIN(A17-Inputs!$B$6+1,24))*Inputs!$B$8) | D17: =IF(C17=0,0,IF(A17<Inputs!$G$7,ROUND(C17*25%,0),ROUND(C17*Inputs!$E$5,0))) | E17: =IF(C17=0,0,IF(A17<Inputs!$G$7,C17-D17,ROUND(C17*Inputs!$E$6,0))) | F17: =C17-D17-E17 | G17: =ROUND((D17*Inputs!$C$25+E17*Inputs!$D$25+F17*Inputs!$E$25)*(1+Inputs!$B$9),2) | H17: =ROUND((D17*Inputs!$C$26+E17*Inputs!$D$26+F17*Inputs!$E$26)*(1+Inputs!$B$9),2) | I17: =ROUND((D17*Inputs!$C$27+E17*Inputs!$D$27+F17*Inputs!$E$27)*(1+Inputs!$B$9),2) | J17: =ROUND((D17*Inputs!$C$28+E17*Inputs!$D$28+F17*Inputs!$E$28)*(1+Inputs!$B$9),2) | K17: =ROUND((D17*Inputs!$C$29+E17*Inputs!$D$29+F17*Inputs!$E$29)*(1+Inputs!$B$9),2) | L17: =ROUND((D17*Inputs!$C$30+E17*Inputs!$D$30+F17*Inputs!$E$30)*(1+Inputs!$B$9),2) | M17: =ROUND((D17*Inputs!$C$31+E17*Inputs!$D$31+F17*Inputs!$E$31)*(1+Inputs!$B$9),2) | N17: =ROUND((D17*Inputs!$C$32+E17*Inputs!$D$32+F17*Inputs!$E$32)*(1+Inputs!$B$9),2) | O17: =ROUND((D17*Inputs!$C$33+E17*Inputs!$D$33+F17*Inputs!$E$33)*(1+Inputs!$B$9),2) | P17: =ROUND((D17*Inputs!$C$34+E17*Inputs!$D$34+F17*Inputs!$E$34)*(1+Inputs!$B$9),2) | Q17: =ROUND((D17*Inputs!$C$35+E17*Inputs!$D$35+F17*Inputs!$E$35)*(1+Inputs!$B$9),2) | R17: =ROUND((D17*Inputs!$C$36+E17*Inputs!$D$36+F17*Inputs!$E$36)*(1+Inputs!$B$9),2) | S17: =ROUND(G17*Inputs!$F$25+H17*Inputs!$F$26+I17*Inputs!$F$27+J17*Inputs!$F$28+K17*Inputs!$F$29+L17*Inputs!$F$30+M17*Inputs!$F$31+N17*Inputs!$F$32+O17*Inputs!$F$33+P17*Inputs!$F$34+Q17*Inputs!$F$35+R17*Inputs!$F$36,2) | T17: =ROUND(S17/100000,2)
... A41: 36 | B41: 47331 | C41: =IF(A41<Inputs!$B$6,0,INDEX(Inputs!$B$41:$B$64,MIN(A41-Inputs!$B$6+1,24))*Inputs!$B$8) | D41: =IF(C41=0,0,IF(A41<Inputs!$G$7,ROUND(C41*25%,0),ROUND(C41*Inputs!$E$5,0))) | E41: =IF(C41=0,0,IF(A41<Inputs!$G$7,C41-D41,ROUND(C41*Inputs!$E$6,0))) | F41: =C41-D41-E41 | G41: =ROUND((D41*Inputs!$C$25+E41*Inputs!$D$25+F41*Inputs!$E$25)*(1+Inputs!$B$9),2) | H41: =ROUND((D41*Inputs!$C$26+E41*Inputs!$D$26+F41*Inputs!$E$26)*(1+Inputs!$B$9),2) | I41: =ROUND((D41*Inputs!$C$27+E41*Inputs!$D$27+F41*Inputs!$E$27)*(1+Inputs!$B$9),2) | J41: =ROUND((D41*Inputs!$C$28+E41*Inputs!$D$28+F41*Inputs!$E$28)*(1+Inputs!$B$9),2) | K41: =ROUND((D41*Inputs!$C$29+E41*Inputs!$D$29+F41*Inputs!$E$29)*(1+Inputs!$B$9),2) | L41: =ROUND((D41*Inputs!$C$30+E41*Inputs!$D$30+F41*Inputs!$E$30)*(1+Inputs!$B$9),2) | M41: =ROUND((D41*Inputs!$C$31+E41*Inputs!$D$31+F41*Inputs!$E$31)*(1+Inputs!$B$9),2) | N41: =ROUND((D41*Inputs!$C$32+E41*Inputs!$D$32+F41*Inputs!$E$32)*(1+Inputs!$B$9),2) | O41: =ROUND((D41*Inputs!$C$33+E41*Inputs!$D$33+F41*Inputs!$E$33)*(1+Inputs!$B$9),2) | P41: =ROUND((D41*Inputs!$C$34+E41*Inputs!$D$34+F41*Inputs!$E$34)*(1+Inputs!$B$9),2) | Q41: =ROUND((D41*Inputs!$C$35+E41*Inputs!$D$35+F41*Inputs!$E$35)*(1+Inputs!$B$9),2) | R41: =ROUND((D41*Inputs!$C$36+E41*Inputs!$D$36+F41*Inputs!$E$36)*(1+Inputs!$B$9),2) | S41: =ROUND(G41*Inputs!$F$25+H41*Inputs!$F$26+I41*Inputs!$F$27+J41*Inputs!$F$28+K41*Inputs!$F$29+L41*Inputs!$F$30+M41*Inputs!$F$31+N41*Inputs!$F$32+O41*Inputs!$F$33+P41*Inputs!$F$34+Q41*Inputs!$F$35+R41*Inputs!$F$36,2) | T41: =ROUND(S41/100000,2)
A42: 36M TOTAL | C42: =SUM(C6:C41) | D42: =SUM(D6:D41) | E42: =SUM(E6:E41) | F42: =SUM(F6:F41) | G42: =SUM(G6:G41) | H42: =SUM(H6:H41) | I42: =SUM(I6:I41) | J42: =SUM(J6:J41) | ... T42: =SUM(T6:T41)

Sheet Component Catalogue
A1: VYNDI Component Catalogue · 66 controlled catalogue items
A2: Catalogue/pricing only. Physical stock remains movement-ledger truth. Procurement parameters P:T are editable planning controls.
A4: Item ID | B4: Category | C4: Subcategory | D4: Brand | E4: Model | F4: Detail | G4: SKU | H4: Unit Price ₹ | I4: Opening Stock | J4: MSL / Reorder | K4: Longitude | L4: Latitude | M4: Altitude | N4: Source | O4: Control Note | P4: Lead Time (mo) | Q4: MOQ | R4: Order Multiple | S4: Payment Lag (mo) | T4: Preferred Supplier | U4: Safety Stock | V4: Supplier Part No. | W4: Currency | X4: GST Rate | Y4: Payment Terms | Z4: Quality Inspection Required? | AA4: Lot Controlled? | AB4: Serial Controlled?
A5: gs-tiagra-4700 | B5: groupset | C5: Mechanical | D5: Shimano | E5: Tiagra 4700 | F5: 2x10 mechanical | G5: SHI-TIA-4700 | H5: 45000 | I5: 0 | J5: 2 | K5: Yes | L5: No | M5: No | N5: GitHub src/lib/data/inventory.ts | O5: Opening stock forced to 0; catalogue is not ledger truth | P5: 2 | Q5: 1 | R5: 1 | S5: 1 | U5: =J5 | W5: INR | Z5: No | AA5: No | AB5: No
A6: gs-105-r7000 | B6: groupset | C6: Mechanical | D6: Shimano | E6: 105 R7000 | F6: 2x11 mechanical | G6: SHI-105-R7000 | H6: 70000 | I6: 0 | J6: 2 | K6: Yes | L6: Yes | M6: No | N6: GitHub src/lib/data/inventory.ts | O6: Opening stock forced to 0; catalogue is not ledger truth | P6: 2 | Q6: 1 | R6: 1 | S6: 1 | U6: =J6 | W6: INR | Z6: No | AA6: No | AB6: No
A7: gs-105-r7150 | B7: groupset | C7: Electronic | D7: Shimano | E7: 105 R7150 Di2 | F7: 2x12 electronic | G7: SHI-105-R7150 | H7: 138000 | I7: 0 | J7: 1 | K7: No | L7: Yes | M7: No | N7: GitHub src/lib/data/inventory.ts | O7: Opening stock forced to 0; catalogue is not ledger truth | P7: 2 | Q7: 1 | R7: 1 | S7: 1 | U7: =J7 | W7: INR | Z7: No | AA7: No | AB7: No
A8: gs-ultegra-r8170 | B8: groupset | C8: Electronic | D8: Shimano | E8: Ultegra R8170 Di2 | F8: 2x12 electronic | G8: SHI-ULT-R8170 | H8: 210000 | I8: 0 | J8: 1 | K8: No | L8: Yes | M8: Yes | N8: GitHub src/lib/data/inventory.ts | O8: Opening stock forced to 0; catalogue is not ledger truth | P8: 2 | Q8: 1 | R8: 1 | S8: 1 | U8: =J8 | W8: INR | Z8: No | AA8: No | AB8: No
A9: gs-duraace-r9270 | B9: groupset | C9: Electronic | D9: Shimano | E9: Dura-Ace R9270 Di2 | F9: 2x12 electronic flagship | G9: SHI-DA-R9270 | H9: 353000 | I9: 0 | J9: 1 | K9: No | L9: No | M9: Yes | N9: GitHub src/lib/data/inventory.ts | O9: Opening stock forced to 0; catalogue is not ledger truth | P9: 2 | Q9: 1 | R9: 1 | S9: 1 | U9: =J9 | W9: INR | Z9: No | AA9: No | AB9: No
A10: gs-rival-axs | B10: groupset | C10: Electronic | D10: SRAM | E10: Rival AXS | F10: 2x12 wireless electronic | G10: SRAM-RIV-AXS | H10: 175000 | I10: 0 | J10: 1 | K10: No | L10: Yes | M10: No | N10: GitHub src/lib/data/inventory.ts | O10: Opening stock forced to 0; catalogue is not ledger truth | P10: 2 | Q10: 1 | R10: 1 | S10: 1 | U10: =J10 | W10: INR | Z10: No | AA10: No | AB10: No
A11: gs-force-axs | B11: groupset | C11: Electronic | D11: SRAM | E11: Force AXS | F11: 2x12 wireless electronic | G11: SRAM-FORCE-AXS | H11: 250000 | I11: 0 | J11: 1 | K11: No | L11: Yes | M11: Yes | N11: GitHub src/lib/data/inventory.ts | O11: Opening stock forced to 0; catalogue is not ledger truth | P11: 2 | Q11: 1 | R11: 1 | S11: 1 | U11: =J11 | W11: INR | Z11: No | AA11: No | AB11: No
A12: gs-red-axs | B12: groupset | C12: Electronic | D12: SRAM | E12: RED AXS | F12: 2x12 wireless flagship | G12: SRAM-RED-AXS | H12: 380000 | I12: 0 | J12: 1 | K12: No | L12: No | M12: Yes | N12: GitHub src/lib/data/inventory.ts | O12: Opening stock forced to 0; catalogue is not ledger truth | P12: 2 | Q12: 1 | R12: 1 | S12: 1 | U12: =J12 | W12: INR | Z12: No | AA12: No | AB12: No
A13: ws-alloy | B13: wheelset | C13: Aluminium | D13: Performance | E13: Performance Alloy | F13: Training / everyday | G13: WH-ALLOY-01 | H13: 30000 | I13: 0 | J13: 3 | K13: Yes | L13: No | M13: No | N13: GitHub src/lib/data/inventory.ts | O13: Opening stock forced to 0; catalogue is not ledger truth | P13: 2 | Q13: 1 | R13: 1 | S13: 1 | U13: =J13 | W13: INR | Z13: No | AA13: No | AB13: No
A14: ws-alloy-30 | B14: wheelset | C14: Aluminium | D14: Light Alloy | E14: 30 Tubeless | F14: 30 mm tubeless-ready | G14: WH-ALLOY-30 | H14: 45000 | I14: 0 | J14: 2 | K14: Yes | L14: Yes | M14: No | N14: GitHub src/lib/data/inventory.ts | O14: Opening stock forced to 0; catalogue is not ledger truth | P14: 2 | Q14: 1 | R14: 1 | S14: 1 | U14: =J14 | W14: INR | Z14: No | AA14: No | AB14: No
A15: ws-alloy-35 | B15: wheelset | C15: Aluminium | D15: Vision | E15: Team 35 | F15: 35 mm alloy aero | G15: WH-VIS-TEAM35 | H15: 55000 | I15: 0 | J15: 1 | K15: Yes | L15: Yes | M15: No | N15: GitHub src/lib/data/inventory.ts | O15: Opening stock forced to 0; catalogue is not ledger truth | P15: 2 | Q15: 1 | R15: 1 | S15: 1 | U15: =J15 | W15: INR | Z15: No | AA15: No | AB15: No
A16: ws-carbon-38 | B16: wheelset | C16: Carbon Aero | D16: Zipp | E16: 303 S | F16: 40 mm carbon tubeless-ready | G16: WH-ZIP-303S | H16: 85000 | I16: 0 | J16: 1 | K16: No | L16: Yes | M16: No | N16: GitHub src/lib/data/inventory.ts | O16: Opening stock forced to 0; catalogue is not ledger truth | P16: 2 | Q16: 1 | R16: 1 | S16: 1 | U16: =J16 | W16: INR | Z16: No | AA16: No | AB16: No
... A71: rm-frame-al-oem | B71: raw-material | C71: Frameset | D71: OEM | E71: Aluminium/OEM frameset | F71: Purchased frameset | G71: FRAMESET-AL-OEM | H71: 45000 | I71: 0 | J71: 0 | K71: Yes | L71: No | M71: No | N71: Inputs!25 | O71: Canonical BOM raw item | P71: 2 | Q71: 1 | R71: 1 | S71: 1 | U71: =J71 | W71: INR | Z71: No | AA71: No | AB71: No
A72: rm-t700 | B72: raw-material | C72: Prepreg | E72: T700 prepreg | F72: Carbon prepreg | G72: RM-T700-PREPREG | H72: 3500 | I72: 0 | J72: 0 | K72: No | L72: Yes | M72: Yes | N72: Inputs!26 | O72: Engineering-controlled | P72: 1 | Q72: 1 | R72: 1 | S72: 1 | U72: =J72 | W72: INR | Z72: No | AA72: No | AB72: No
A73: rm-t800 | B73: raw-material | C73: Prepreg | E73: T800 prepreg | F73: Carbon prepreg | G73: RM-T800-PREPREG | H73: 6500 | I73: 0 | J73: 0 | K73: No | L73: Yes | M73: Yes | N73: Inputs!27 | O73: Engineering-controlled | P73: 1 | Q73: 1 | R73: 1 | S73: 1 | U73: =J73 | W73: INR | Z73: No | AA73: No | AB73: No
A74: rm-resin | B74: raw-material | C74: Resin | E74: Resin & bonding system | F74: Resin / adhesive | G74: RM-RESIN-BOND | H74: 1800 | I74: 0 | J74: 0 | K74: No | L74: Yes | M74: Yes | N74: Inputs!28 | O74: Engineering-controlled | P74: 1 | Q74: 1 | R74: 1 | S74: 1 | U74: =J74 | W74: INR | Z74: No | AA74: No | AB74: No
A75: rm-paint | B75: raw-material | C75: Finishing | E75: Paint & clear coat | F75: Paint system | G75: RM-PAINT-CLEAR | H75: 2200 | I75: 0 | J75: 0 | K75: Yes | L75: Yes | M75: Yes | N75: Inputs!29 | O75: Engineering-controlled | P75: 1 | Q75: 1 | R75: 1 | S75: 1 | U75: =J75 | W75: INR | Z75: No | AA75: No | AB75: No
A76: pkg-kit | B76: packaging | C76: Shipment | E76: Packaging kit | F76: Shipment packaging | G76: PKG-KIT | H76: 2500 | I76: 0 | J76: 0 | K76: Yes | L76: Yes | M76: Yes | N76: Inputs!36 | O76: Canonical BOM packaging | P76: 1 | Q76: 1 | R76: 1 | S76: 1 | U76: =J76 | W76: INR | Z76: No | AA76: No | AB76: No

Sheet Inventory Movements
A1: Inventory Movement Ledger · FIFO-supporting source of physical stock truth
A3: Movement ID | B3: Date | C3: SKU | D3: Type | E3: Qty In | F3: Qty Out | G3: Unit Cost ₹ | H3: Lot / PO | I3: Job Card | J3: Quality Status | K3: Posted? | L3: Evidence / Note | M3: Truth Class | N3: Revision | O3: Source Ref | P3: Posted At | Q3: Posted By
A4: =IF(C4="","","MOV-"&TEXT(ROW()-3,"0000")) | J4: Released | K4: No | M4: =IF(A4="","",IF(K4="Yes","Actual","Plan")) | N4: 1
A5: =IF(C5="","","MOV-"&TEXT(ROW()-3,"0000")) | J5: Released | K5: No | M5: =IF(A5="","",IF(K5="Yes","Actual","Plan")) | N5: 1
A6: =IF(C6="","","MOV-"&TEXT(ROW()-3,"0000")) | J6: Released | K6: No | M6: =IF(A6="","",IF(K6="Yes","Actual","Plan")) | N6: 1
A7: =IF(C7="","","MOV-"&TEXT(ROW()-3,"0000")) | J7: Released | K7: No | M7: =IF(A7="","",IF(K7="Yes","Actual","Plan")) | N7: 1
A8: =IF(C8="","","MOV-"&TEXT(ROW()-3,"0000")) | J8: Released | K8: No | M8: =IF(A8="","",IF(K8="Yes","Actual","Plan")) | N8: 1
A9: =IF(C9="","","MOV-"&TEXT(ROW()-3,"0000")) | J9: Released | K9: No | M9: =IF(A9="","",IF(K9="Yes","Actual","Plan")) | N9: 1
A10: =IF(C10="","","MOV-"&TEXT(ROW()-3,"0000")) | J10: Released | K10: No | M10: =IF(A10="","",IF(K10="Yes","Actual","Plan")) | N10: 1
A11: =IF(C11="","","MOV-"&TEXT(ROW()-3,"0000")) | J11: Released | K11: No | M11: =IF(A11="","",IF(K11="Yes","Actual","Plan")) | N11: 1
A12: =IF(C12="","","MOV-"&TEXT(ROW()-3,"0000")) | J12: Released | K12: No | M12: =IF(A12="","",IF(K12="Yes","Actual","Plan")) | N12: 1
A13: =IF(C13="","","MOV-"&TEXT(ROW()-3,"0000")) | J13: Released | K13: No | M13: =IF(A13="","",IF(K13="Yes","Actual","Plan")) | N13: 1
A14: =IF(C14="","","MOV-"&TEXT(ROW()-3,"0000")) | J14: Released | K14: No | M14: =IF(A14="","",IF(K14="Yes","Actual","Plan")) | N14: 1
A15: =IF(C15="","","MOV-"&TEXT(ROW()-3,"0000")) | J15: Released | K15: No | M15: =IF(A15="","",IF(K15="Yes","Actual","Plan")) | N15: 1
... A203: =IF(C203="","","MOV-"&TEXT(ROW()-3,"0000")) | J203: Released | K203: No | M203: =IF(A203="","",IF(K203="Yes","Actual","Plan")) | N203: 1

Sheet Reservations
A1: Reservation Ledger · committed demand allocation before FIFO issue
A3: Reservation ID | B3: Order ID | C3: Order Rev | D3: Job Card | E3: SKU | F3: Qty Required | G3: Qty Reserved | H3: Status | I3: Release / Issue Ref | J3: Note | K3: Truth Class | L3: Revision | M3: Created At | N3: Approved By
A4: =IF(E4="","","RES-"&TEXT(ROW()-3,"0000")) | H4: Draft | K4: =IF(A4="","",IF(H4="Consumed","Actual",IF(H4="Active","Committed","Plan"))) | L4: 1
A5: =IF(E5="","","RES-"&TEXT(ROW()-3,"0000")) | H5: Draft | K5: =IF(A5="","",IF(H5="Consumed","Actual",IF(H5="Active","Committed","Plan"))) | L5: 1
A6: =IF(E6="","","RES-"&TEXT(ROW()-3,"0000")) | H6: Draft | K6: =IF(A6="","",IF(H6="Consumed","Actual",IF(H6="Active","Committed","Plan"))) | L6: 1
A7: =IF(E7="","","RES-"&TEXT(ROW()-3,"0000")) | H7: Draft | K7: =IF(A7="","",IF(H7="Consumed","Actual",IF(H7="Active","Committed","Plan"))) | L7: 1
A8: =IF(E8="","","RES-"&TEXT(ROW()-3,"0000")) | H8: Draft | K8: =IF(A8="","",IF(H8="Consumed","Actual",IF(H8="Active","Committed","Plan"))) | L8: 1
A9: =IF(E9="","","RES-"&TEXT(ROW()-3,"0000")) | H9: Draft | K9: =IF(A9="","",IF(H9="Consumed","Actual",IF(H9="Active","Committed","Plan"))) | L9: 1
A10: =IF(E10="","","RES-"&TEXT(ROW()-3,"0000")) | H10: Draft | K10: =IF(A10="","",IF(H10="Consumed","Actual",IF(H10="Active","Committed","Plan"))) | L10: 1
A11: =IF(E11="","","RES-"&TEXT(ROW()-3,"0000")) | H11: Draft | K11: =IF(A11="","",IF(H11="Consumed","Actual",IF(H11="Active","Committed","Plan"))) | L11: 1
A12: =IF(E12="","","RES-"&TEXT(ROW()-3,"0000")) | H12: Draft | K12: =IF(A12="","",IF(H12="Consumed","Actual",IF(H12="Active","Committed","Plan"))) | L12: 1
A13: =IF(E13="","","RES-"&TEXT(ROW()-3,"0000")) | H13: Draft | K13: =IF(A13="","",IF(H13="Consumed","Actual",IF(H13="Active","Committed","Plan"))) | L13: 1
A14: =IF(E14="","","RES-"&TEXT(ROW()-3,"0000")) | H14: Draft | K14: =IF(A14="","",IF(H14="Consumed","Actual",IF(H14="Active","Committed","Plan"))) | L14: 1
A15: =IF(E15="","","RES-"&TEXT(ROW()-3,"0000")) | H15: Draft | K15: =IF(A15="","",IF(H15="Consumed","Actual",IF(H15="Active","Committed","Plan"))) | L15: 1
... A103: =IF(E103="","","RES-"&TEXT(ROW()-3,"0000")) | H103: Draft | K103: =IF(A103="","",IF(H103="Consumed","Actual",IF(H103="Active","Committed","Plan"))) | L103: 1

Sheet Master Inventory
A1: Master Inventory · canonical balance, ATP, MSL and procurement signal
A3: SKU | B3: Category | C3: Item | D3: Unit Price ₹ | E3: MSL | F3: Receipts | G3: Issues | H3: On Hand | I3: Active Reservations | J3: ATP | K3: Shortage to MSL | L3: Health | M3: Suggested Order Qty | N3: Inventory Value ₹
A4: ='Component Catalogue'!G5 | B4: ='Component Catalogue'!B5 | C4: ='Component Catalogue'!E5 | D4: ='Component Catalogue'!H5 | E4: ='Component Catalogue'!J5 | F4: =SUMIFS('Inventory Movements'!$E$4:$E$5003,'Inventory Movements'!$C$4:$C$5003,$A4,'Inventory Movements'!$K$4:$K$5003,"Yes",'Inventory Movements'!$J$4:$J$5003,"Released") | G4: =SUMIFS('Inventory Movements'!$F$4:$F$5003,'Inventory Movements'!$C$4:$C$5003,$A4,'Inventory Movements'!$K$4:$K$5003,"Yes") | H4: =F4-G4 | I4: =SUMIFS(Reservations!$G$4:$G$2003,Reservations!$E$4:$E$2003,$A4,Reservations!$H$4:$H$2003,"Active") | J4: =MAX(0,H4-I4) | K4: =MAX(0,E4-J4) | L4: =IF(J4=0,"OUT",IF(J4<E4,"LOW","OK")) | M4: =K4 | N4: =H4*D4
A5: ='Component Catalogue'!G6 | B5: ='Component Catalogue'!B6 | C5: ='Component Catalogue'!E6 | D5: ='Component Catalogue'!H6 | E5: ='Component Catalogue'!J6 | F5: =SUMIFS('Inventory Movements'!$E$4:$E$5003,'Inventory Movements'!$C$4:$C$5003,$A5,'Inventory Movements'!$K$4:$K$5003,"Yes",'Inventory Movements'!$J$4:$J$5003,"Released") | G5: =SUMIFS('Inventory Movements'!$F$4:$F$5003,'Inventory Movements'!$C$4:$C$5003,$A5,'Inventory Movements'!$K$4:$K$5003,"Yes") | H5: =F5-G5 | I5: =SUMIFS(Reservations!$G$4:$G$2003,Reservations!$E$4:$E$2003,$A5,Reservations!$H$4:$H$2003,"Active") | J5: =MAX(0,H5-I5) | K5: =MAX(0,E5-J5) | L5: =IF(J5=0,"OUT",IF(J5<E5,"LOW","OK")) | M5: =K5 | N5: =H5*D5
A6: ='Component Catalogue'!G7 | B6: ='Component Catalogue'!B7 | C6: ='Component Catalogue'!E7 | D6: ='Component Catalogue'!H7 | E6: ='Component Catalogue'!J7 | F6: =SUMIFS('Inventory Movements'!$E$4:$E$5003,'Inventory Movements'!$C$4:$C$5003,$A6,'Inventory Movements'!$K$4:$K$5003,"Yes",'Inventory Movements'!$J$4:$J$5003,"Released") | G6: =SUMIFS('Inventory Movements'!$F$4:$F$5003,'Inventory Movements'!$C$4:$C$5003,$A6,'Inventory Movements'!$K$4:$K$5003,"Yes") | H6: =F6-G6 | I6: =SUMIFS(Reservations!$G$4:$G$2003,Reservations!$E$4:$E$2003,$A6,Reservations!$H$4:$H$2003,"Active") | J6: =MAX(0,H6-I6) | K6: =MAX(0,E6-J6) | L6: =IF(J6=0,"OUT",IF(J6<E6,"LOW","OK")) | M6: =K6 | N6: =H6*D6
A7: ='Component Catalogue'!G8 | B7: ='Component Catalogue'!B8 | C7: ='Component Catalogue'!E8 | D7: ='Component Catalogue'!H8 | E7: ='Component Catalogue'!J8 | F7: =SUMIFS('Inventory Movements'!$E$4:$E$5003,'Inventory Movements'!$C$4:$C$5003,$A7,'Inventory Movements'!$K$4:$K$5003,"Yes",'Inventory Movements'!$J$4:$J$5003,"Released") | G7: =SUMIFS('Inventory Movements'!$F$4:$F$5003,'Inventory Movements'!$C$4:$C$5003,$A7,'Inventory Movements'!$K$4:$K$5003,"Yes") | H7: =F7-G7 | I7: =SUMIFS(Reservations!$G$4:$G$2003,Reservations!$E$4:$E$2003,$A7,Reservations!$H$4:$H$2003,"Active") | J7: =MAX(0,H7-I7) | K7: =MAX(0,E7-J7) | L7: =IF(J7=0,"OUT",IF(J7<E7,"LOW","OK")) | M7: =K7 | N7: =H7*D7
A8: ='Component Catalogue'!G9 | B8: ='Component Catalogue'!B9 | C8: ='Component Catalogue'!E9 | D8: ='Component Catalogue'!H9 | E8: ='Component Catalogue'!J9 | F8: =SUMIFS('Inventory Movements'!$E$4:$E$5003,'Inventory Movements'!$C$4:$C$5003,$A8,'Inventory Movements'!$K$4:$K$5003,"Yes",'Inventory Movements'!$J$4:$J$5003,"Released") | G8: =SUMIFS('Inventory Movements'!$F$4:$F$5003,'Inventory Movements'!$C$4:$C$5003,$A8,'Inventory Movements'!$K$4:$K$5003,"Yes") | H8: =F8-G8 | I8: =SUMIFS(Reservations!$G$4:$G$2003,Reservations!$E$4:$E$2003,$A8,Reservations!$H$4:$H$2003,"Active") | J8: =MAX(0,H8-I8) | K8: =MAX(0,E8-J8) | L8: =IF(J8=0,"OUT",IF(J8<E8,"LOW","OK")) | M8: =K8 | N8: =H8*D8
A9: ='Component Catalogue'!G10 | B9: ='Component Catalogue'!B10 | C9: ='Component Catalogue'!E10 | D9: ='Component Catalogue'!H10 | E9: ='Component Catalogue'!J10 | F9: =SUMIFS('Inventory Movements'!$E$4:$E$5003,'Inventory Movements'!$C$4:$C$5003,$A9,'Inventory Movements'!$K$4:$K$5003,"Yes",'Inventory Movements'!$J$4:$J$5003,"Released") | G9: =SUMIFS('Inventory Movements'!$F$4:$F$5003,'Inventory Movements'!$C$4:$C$5003,$A9,'Inventory Movements'!$K$4:$K$5003,"Yes") | H9: =F9-G9 | I9: =SUMIFS(Reservations!$G$4:$G$2003,Reservations!$E$4:$E$2003,$A9,Reservations!$H$4:$H$2003,"Active") | J9: =MAX(0,H9-I9) | K9: =MAX(0,E9-J9) | L9: =IF(J9=0,"OUT",IF(J9<E9,"LOW","OK")) | M9: =K9 | N9: =H9*D9
A10: ='Component Catalogue'!G11 | B10: ='Component Catalogue'!B11 | C10: ='Component Catalogue'!E11 | D10: ='Component Catalogue'!H11 | E10: ='Component Catalogue'!J11 | F10: =SUMIFS('Inventory Movements'!$E$4:$E$5003,'Inventory Movements'!$C$4:$C$5003,$A10,'Inventory Movements'!$K$4:$K$5003,"Yes",'Inventory Movements'!$J$4:$J$5003,"Released") | G10: =SUMIFS('Inventory Movements'!$F$4:$F$5003,'Inventory Movements'!$C$4:$C$5003,$A10,'Inventory Movements'!$K$4:$K$5003,"Yes") | H10: =F10-G10 | I10: =SUMIFS(Reservations!$G$4:$G$2003,Reservations!$E$4:$E$2003,$A10,Reservations!$H$4:$H$2003,"Active") | J10: =MAX(0,H10-I10) | K10: =MAX(0,E10-J10) | L10: =IF(J10=0,"OUT",IF(J10<E10,"LOW","OK")) | M10: =K10 | N10: =H10*D10
A11: ='Component Catalogue'!G12 | B11: ='Component Catalogue'!B12 | C11: ='Component Catalogue'!E12 | D11: ='Component Catalogue'!H12 | E11: ='Component Catalogue'!J12 | F11: =SUMIFS('Inventory Movements'!$E$4:$E$5003,'Inventory Movements'!$C$4:$C$5003,$A11,'Inventory Movements'!$K$4:$K$5003,"Yes",'Inventory Movements'!$J$4:$J$5003,"Released") | G11: =SUMIFS('Inventory Movements'!$F$4:$F$5003,'Inventory Movements'!$C$4:$C$5003,$A11,'Inventory Movements'!$K$4:$K$5003,"Yes") | H11: =F11-G11 | I11: =SUMIFS(Reservations!$G$4:$G$2003,Reservations!$E$4:$E$2003,$A11,Reservations!$H$4:$H$2003,"Active") | J11: =MAX(0,H11-I11) | K11: =MAX(0,E11-J11) | L11: =IF(J11=0,"OUT",IF(J11<E11,"LOW","OK")) | M11: =K11 | N11: =H11*D11
A12: ='Component Catalogue'!G13 | B12: ='Component Catalogue'!B13 | C12: ='Component Catalogue'!E13 | D12: ='Component Catalogue'!H13 | E12: ='Component Catalogue'!J13 | F12: =SUMIFS('Inventory Movements'!$E$4:$E$5003,'Inventory Movements'!$C$4:$C$5003,$A12,'Inventory Movements'!$K$4:$K$5003,"Yes",'Inventory Movements'!$J$4:$J$5003,"Released") | G12: =SUMIFS('Inventory Movements'!$F$4:$F$5003,'Inventory Movements'!$C$4:$C$5003,$A12,'Inventory Movements'!$K$4:$K$5003,"Yes") | H12: =F12-G12 | I12: =SUMIFS(Reservations!$G$4:$G$2003,Reservations!$E$4:$E$2003,$A12,Reservations!$H$4:$H$2003,"Active") | J12: =MAX(0,H12-I12) | K12: =MAX(0,E12-J12) | L12: =IF(J12=0,"OUT",IF(J12<E12,"LOW","OK")) | M12: =K12 | N12: =H12*D12
A13: ='Component Catalogue'!G14 | B13: ='Component Catalogue'!B14 | C13: ='Component Catalogue'!E14 | D13: ='Component Catalogue'!H14 | E13: ='Component Catalogue'!J14 | F13: =SUMIFS('Inventory Movements'!$E$4:$E$5003,'Inventory Movements'!$C$4:$C$5003,$A13,'Inventory Movements'!$K$4:$K$5003,"Yes",'Inventory Movements'!$J$4:$J$5003,"Released") | G13: =SUMIFS('Inventory Movements'!$F$4:$F$5003,'Inventory Movements'!$C$4:$C$5003,$A13,'Inventory Movements'!$K$4:$K$5003,"Yes") | H13: =F13-G13 | I13: =SUMIFS(Reservations!$G$4:$G$2003,Reservations!$E$4:$E$2003,$A13,Reservations!$H$4:$H$2003,"Active") | J13: =MAX(0,H13-I13) | K13: =MAX(0,E13-J13) | L13: =IF(J13=0,"OUT",IF(J13<E13,"LOW","OK")) | M13: =K13 | N13: =H13*D13
A14: ='Component Catalogue'!G15 | B14: ='Component Catalogue'!B15 | C14: ='Component Catalogue'!E15 | D14: ='Component Catalogue'!H15 | E14: ='Component Catalogue'!J15 | F14: =SUMIFS('Inventory Movements'!$E$4:$E$5003,'Inventory Movements'!$C$4:$C$5003,$A14,'Inventory Movements'!$K$4:$K$5003,"Yes",'Inventory Movements'!$J$4:$J$5003,"Released") | G14: =SUMIFS('Inventory Movements'!$F$4:$F$5003,'Inventory Movements'!$C$4:$C$5003,$A14,'Inventory Movements'!$K$4:$K$5003,"Yes") | H14: =F14-G14 | I14: =SUMIFS(Reservations!$G$4:$G$2003,Reservations!$E$4:$E$2003,$A14,Reservations!$H$4:$H$2003,"Active") | J14: =MAX(0,H14-I14) | K14: =MAX(0,E14-J14) | L14: =IF(J14=0,"OUT",IF(J14<E14,"LOW","OK")) | M14: =K14 | N14: =H14*D14
A15: ='Component Catalogue'!G16 | B15: ='Component Catalogue'!B16 | C15: ='Component Catalogue'!E16 | D15: ='Component Catalogue'!H16 | E15: ='Component Catalogue'!J16 | F15: =SUMIFS('Inventory Movements'!$E$4:$E$5003,'Inventory Movements'!$C$4:$C$5003,$A15,'Inventory Movements'!$K$4:$K$5003,"Yes",'Inventory Movements'!$J$4:$J$5003,"Released") | G15: =SUMIFS('Inventory Movements'!$F$4:$F$5003,'Inventory Movements'!$C$4:$C$5003,$A15,'Inventory Movements'!$K$4:$K$5003,"Yes") | H15: =F15-G15 | I15: =SUMIFS(Reservations!$G$4:$G$2003,Reservations!$E$4:$E$2003,$A15,Reservations!$H$4:$H$2003,"Active") | J15: =MAX(0,H15-I15) | K15: =MAX(0,E15-J15) | L15: =IF(J15=0,"OUT",IF(J15<E15,"LOW","OK")) | M15: =K15 | N15: =H15*D15
... A75: ='Component Catalogue'!G76 | B75: ='Component Catalogue'!B76 | C75: ='Component Catalogue'!E76 | D75: ='Component Catalogue'!H76 | E75: ='Component Catalogue'!J76 | F75: =SUMIFS('Inventory Movements'!$E$4:$E$5003,'Inventory Movements'!$C$4:$C$5003,$A75,'Inventory Movements'!$K$4:$K$5003,"Yes",'Inventory Movements'!$J$4:$J$5003,"Released") | G75: =SUMIFS('Inventory Movements'!$F$4:$F$5003,'Inventory Movements'!$C$4:$C$5003,$A75,'Inventory Movements'!$K$4:$K$5003,"Yes") | H75: =F75-G75 | I75: =SUMIFS(Reservations!$G$4:$G$2003,Reservations!$E$4:$E$2003,$A75,Reservations!$H$4:$H$2003,"Active") | J75: =MAX(0,H75-I75) | K75: =MAX(0,E75-J75) | L75: =IF(J75=0,"OUT",IF(J75<E75,"LOW","OK")) | M75: =K75 | N75: =H75*D75

Sheet BOM Mapping
A1: Approved BOM → SKU Mapping · planning defaults for Longitude / Latitude / Altitude
A2: CANONICAL BOM AUTHORITY. J:L hold model-specific Qty/Bike; MRP/procurement/job material logic must reference this sheet only.
A3: BOM Line | B3: Category | C3: Longitude SKU | D3: Latitude SKU | E3: Altitude SKU | F3: Qty / bike | G3: Unit | H3: Revision | I3: Status | J3: Qty Longitude | K3: Qty Latitude | L3: Qty Altitude
A4: Drivetrain | B4: groupset | C4: SHI-105-R7000 | D4: SHI-105-R7150 | E4: SHI-ULT-R8170 | F4: 1 | G4: set | H4: BOM-PLAN-1 | I4: Approved | J4: =F4 | K4: =F4 | L4: =F4
A5: Wheelset | B5: wheelset | C5: WH-ALLOY-30 | D5: WH-ZIP-303S | E5: WH-CARB-50 | F5: 1 | G5: set | H5: BOM-PLAN-1 | I5: Approved | J5: =F5 | K5: =F5 | L5: =F5
A6: Tyres | B6: tyre | C6: TY-RUBINO-PRO-PAIR | D6: TY-GP5000-PAIR | E6: TY-CORSA-PRO-PAIR | F6: 1 | G6: pair | H6: BOM-PLAN-1 | I6: Approved | J6: =F6 | K6: =F6 | L6: =F6
A7: Handlebar | B7: handlebar | C7: HB-AL-420 | D7: HB-CB-420 | E7: HB-CB-420 | F7: 1 | G7: ea | H7: BOM-PLAN-1 | I7: Approved | J7: =F7 | K7: =F7 | L7: =F7
A8: Stem | B8: stem | C8: ST-AL-090 | D8: ST-AL-100 | E8: ST-INT-100 | F8: 1 | G8: ea | H8: BOM-PLAN-1 | I8: Approved | J8: =F8 | K8: =F8 | L8: =F8
A9: Saddle | B9: saddle | C9: SD-M-BL | D9: SD-M-NL | E9: SD-M-NS | F9: 1 | G9: ea | H9: BOM-PLAN-1 | I9: Approved | J9: =F9 | K9: =F9 | L9: =F9
A10: Thru axle | B10: thruaxle | C10: TA-ROAD-CORE | D10: TA-ROAD-CORE | E10: TA-TI-ROAD | F10: 1 | G10: set | H10: BOM-PLAN-1 | I10: Approved | J10: =F10 | K10: =F10 | L10: =F10
A11: Bottom bracket | B11: bottom-bracket | C11: BB-BSA-ROAD | D11: BB-T47I-855 | E11: BB-T47I-855 | F11: 1 | G11: ea | H11: BOM-PLAN-1 | I11: Approved | J11: =F11 | K11: =F11 | L11: =F11
A12: Bottle cages | B12: bottle-cage | C12: BC-PLASTIC-01 | D12: BC-CARBON-01 | E12: BC-CARBON-01 | F12: 2 | G12: ea | H12: BOM-PLAN-1 | I12: Approved | J12: =F12 | K12: =F12 | L12: =F12
A13: Tool pouch | B13: tool-pouch | C13: TP-INTEGRATED-01 | D13: TP-INTEGRATED-01 | E13: TP-INTEGRATED-01 | F13: 1 | G13: ea | H13: BOM-PLAN-1 | I13: Approved | J13: =F13 | K13: =F13 | L13: =F13
A14: Computer bracket | B14: bracket | C14: BR-COMP-01 | D14: BR-COMP-01 | E14: BR-COMP-01 | F14: 1 | G14: ea | H14: BOM-PLAN-1 | I14: Approved | J14: =F14 | K14: =F14 | L14: =F14
A15: Light bracket | B15: bracket | C15: BR-LIGHT-01 | D15: BR-LIGHT-01 | E15: BR-LIGHT-01 | F15: 1 | G15: ea | H15: BOM-PLAN-1 | I15: Approved | J15: =F15 | K15: =F15 | L15: =F15
... A17: M6 fasteners | B17: fastener | C17: HW-ALLEN-M6 | D17: HW-ALLEN-M6 | E17: HW-ALLEN-M6 | F17: 2 | G17: ea | H17: BOM-PLAN-1 | I17: Approved | J17: =F17 | K17: =F17 | L17: =F17
A18: Aluminium/OEM frameset | B18: raw-material | C18: FRAMESET-AL-OEM | F18: 1 | G18: set | H18: BOM-PLAN-1 | I18: Approved | J18: 1 | K18: 0 | L18: 0
A19: T700 prepreg | B19: raw-material | D19: RM-T700-PREPREG | E19: RM-T700-PREPREG | F19: 1 | G19: kg | H19: BOM-PLAN-1 | I19: Approved | J19: 0 | K19: 3.2 | L19: 2.5
A20: T800 prepreg | B20: raw-material | D20: RM-T800-PREPREG | E20: RM-T800-PREPREG | F20: 1 | G20: kg | H20: BOM-PLAN-1 | I20: Approved | J20: 0 | K20: 1.3 | L20: 2.2
A21: Resin & bonding system | B21: raw-material | D21: RM-RESIN-BOND | E21: RM-RESIN-BOND | F21: 1 | G21: kg | H21: BOM-PLAN-1 | I21: Approved | J21: 0 | K21: 0.8 | L21: 0.9
A22: Paint & clear coat | B22: raw-material | C22: RM-PAINT-CLEAR | D22: RM-PAINT-CLEAR | E22: RM-PAINT-CLEAR | F22: 1 | G22: L | H22: BOM-PLAN-1 | I22: Approved | J22: 0.35 | K22: 0.35 | L22: 0.35
A23: Packaging kit | B23: packaging | C23: PKG-KIT | D23: PKG-KIT | E23: PKG-KIT | F23: 1 | G23: kit | H23: BOM-PLAN-1 | I23: Approved | J23: 1 | K23: 1 | L23: 1

Sheet Sales Orders
A1: Commercial Order Register · confirmed orders become committed demand
